Workbook
Name ALPINE: #REF!
Name ALPINE: #REF!
Name ALTWEISS: #REF!
Name ALTWEISS: #REF!
Name BLANCO: #REF!
Name BLANCO: #REF!
Name BLANCO_: #REF!
Name BLANCO_: #REF!
Name CIELO3: INDIRECT(' CIELORRASO EXT'!$C$3)
Name CIELO3: INDIRECT('[1] CIELORRASO INT '!$C$3)
Name CIELO3: INDIRECT(#REF!)
Name CIELORASO: INDIRECT(' CIELORRASO EXT'!$C$3)
Name CIELORASO: INDIRECT('[1] CIELORRASO INT '!$C$3)
Name CIELORASO: INDIRECT(#REF!)
Name CIELORASO2: INDIRECT(' CIELORRASO EXT'!$C$3)
Name CIELORASO2: INDIRECT('[1] CIELORRASO INT '!$C$3)
Name CIELORASO2: INDIRECT(#REF!)
Name CIELORASO5: INDIRECT(' CIELORRASO EXT'!$C$3)
Name CIELORASO5: INDIRECT('[1] CIELORRASO INT '!$C$3)
Name CIELORASO5: INDIRECT(#REF!)
Name COLOR: INDIRECT('[1]WALL PANELS EXT'!$C$5)
Name COLOR: INDIRECT('[1]WALL PANELS EXT'!$C$5)
Name COLOR: INDIRECT(#REF!)
Name CONCRET_C: #REF!
Name CONCRET_C: #REF!
Name CONCRET_C_: #REF!
Name CONCRET_C_: #REF!
Name CONCRET_WITE: #REF!
Name CONCRET_WITE: #REF!
Name CONCRET_WITE_: #REF!
Name CONCRET_WITE_: #REF!
Name EUCALIPTUS: #REF!
Name EUCALIPTUS: #REF!
Name EUCALIPTUS_: #REF!
Name EUCALIPTUS_: #REF!
Name EUCALYPTUS: #REF!
Name EUCALYPTUS: #REF!
Name foil: INDIRECT('[1]WALL PANELS EXT'!$C$5)
Name foil: INDIRECT('[1]WALL PANELS EXT'!$C$5)
Name foil: INDIRECT(#REF!)
Name foil2: INDIRECT('[1]WALL PANELS EXT'!$F$5)
Name foil2: INDIRECT('[1]WALL PANELS EXT'!$F$5)
Name foil2: INDIRECT(#REF!)
Name foil3: INDIRECT('[1] WALL PANELLS INT'!$C$5)
Name foil3: INDIRECT('[1] WALL PANELLS INT'!$C$5)
Name foil3: INDIRECT(#REF!)
Name FOIL4: INDIRECT('[1] WALL PANELLS INT'!$C$5)
Name FOIL4: INDIRECT('[1] WALL PANELLS INT'!$C$5)
Name FOIL4: INDIRECT(#REF!)
Name FOIL5: INDIRECT('[1] WALL PANELLS INT'!$C$5)
Name FOIL5: INDIRECT('[1] WALL PANELLS INT'!$C$5)
Name FOIL5: INDIRECT(#REF!)
Name foil6: INDIRECT('[1] WALL PANELLS INT'!$F$5)
Name foil6: INDIRECT('[1] WALL PANELLS INT'!$F$5)
Name foil6: INDIRECT(#REF!)
Name GOLDBRONZE: #REF!
Name GOLDBRONZE: #REF!
Name GOLDEN_OK: #REF!
Name GOLDEN_OK: #REF!
Name GOLDENOK: #REF!

Sheet PLANILLA PEDIDO
C2: DESCUENTOS | E2: DESCUENTOS | G2: DESCUENTOS | J2: =+TODAY() -> 46148
B3: PERFILES PVC | C3: 0 | D3: WALL PANELS | E3: 0 | F3: PISOS | G3: 0
B4: REFUERZOS | C4: 0 | D4: CIELORASO | E4: 0 | F4: DECKS | G4: 0
B5: ACCESORIOS | C5: 0 | D5: TUBULARES | E5: 0 | F5: ZOCALOS | G5: 0 | J5: vers. 2
B7: Cliente: | K7: PLANILLA PEDIDO NAC. MAYO 2026
B8: Obra / Referencia: | K8: SUB TOTAL | L8: =SUM(L11:L123) -> 0
B10: Codigo | C10: Cantidad | D10: Descripcion | E10: Masa | F10: Color | G10: Unitario en u$s | H10: Presentacion ML / UN | L10: Total en u$s
D11: =IFERROR(VLOOKUP(B11,'TARIFA MASTER'!$B$5:$C$3741,2,0),0) -> 0 | E11: =IFERROR(VLOOKUP(B11,'TARIFA MASTER'!B10:L3462,3,0),0) -> 0 | F11: =IFERROR(VLOOKUP(B11,'TARIFA MASTER'!$B$15:$E$3702,4,0),0) -> 0 | G11: =IFERROR(VLOOKUP(B11,'TARIFA MASTER'!$B$5:$L$4699,11,0),0) -> 0 | H11: =IFERROR(VLOOKUP(B11,'TARIFA MASTER'!$B$5:$J$3754,5,0),0) -> 0 | K11: =IFERROR(VLOOKUP(B11,'TARIFA MASTER'!$B$5:$G$3752,6,0),0) -> 0 | L11: =+G11*C11 -> 0 | M11: =IFERROR(VLOOKUP(B11,[2]PESOS!A$2:D$3072,4,0),0) -> 0 | N11: =+M11*C11 -> 0
D12: =IFERROR(VLOOKUP(B12,'TARIFA MASTER'!$B$5:$C$3741,2,0),0) -> 0 | E12: =IFERROR(VLOOKUP(B12,'TARIFA MASTER'!B11:L3463,3,0),0) -> 0 | F12: =IFERROR(VLOOKUP(B12,'TARIFA MASTER'!$B$15:$E$3702,4,0),0) -> 0 | G12: =IFERROR(VLOOKUP(B12,'TARIFA MASTER'!$B$5:$L$4699,11,0),0) -> 0 | H12: =IFERROR(VLOOKUP(B12,'TARIFA MASTER'!$B$5:$J$3754,5,0),0) -> 0 | K12: =IFERROR(VLOOKUP(B12,'TARIFA MASTER'!$B$5:$G$3752,6,0),0) -> 0 | L12: =+G12*C12 -> 0 | M12: =IFERROR(VLOOKUP(B12,[2]PESOS!A$2:D$3072,4,0),0) -> 0 | N12: =+M12*C12 -> 0
D13: =IFERROR(VLOOKUP(B13,'TARIFA MASTER'!$B$5:$C$3741,2,0),0) -> 0 | E13: =IFERROR(VLOOKUP(B13,'TARIFA MASTER'!B11:L3464,3,0),0) -> 0 | F13: =IFERROR(VLOOKUP(B13,'TARIFA MASTER'!$B$15:$E$3702,4,0),0) -> 0 | G13: =IFERROR(VLOOKUP(B13,'TARIFA MASTER'!$B$5:$L$4699,11,0),0) -> 0 | H13: =IFERROR(VLOOKUP(B13,'TARIFA MASTER'!$B$5:$J$3754,5,0),0) -> 0 | K13: =IFERROR(VLOOKUP(B13,'TARIFA MASTER'!$B$5:$G$3752,6,0),0) -> 0 | L13: =+G13*C13 -> 0 | M13: =IFERROR(VLOOKUP(B13,[2]PESOS!A$2:D$3072,4,0),0) -> 0 | N13: =+M13*C13 -> 0
D14: =IFERROR(VLOOKUP(B14,'TARIFA MASTER'!$B$5:$C$3741,2,0),0) -> 0 | E14: =IFERROR(VLOOKUP(B14,'TARIFA MASTER'!B11:L3465,3,0),0) -> 0 | F14: =IFERROR(VLOOKUP(B14,'TARIFA MASTER'!$B$15:$E$3702,4,0),0) -> 0 | G14: =IFERROR(VLOOKUP(B14,'TARIFA MASTER'!$B$5:$L$4699,11,0),0) -> 0 | H14: =IFERROR(VLOOKUP(B14,'TARIFA MASTER'!$B$5:$J$3754,5,0),0) -> 0 | K14: =IFERROR(VLOOKUP(B14,'TARIFA MASTER'!$B$5:$G$3752,6,0),0) -> 0 | L14: =+G14*C14 -> 0 | M14: =IFERROR(VLOOKUP(B14,[2]PESOS!A$2:D$3072,4,0),0) -> 0 | N14: =+M14*C14 -> 0
D15: =IFERROR(VLOOKUP(B15,'TARIFA MASTER'!$B$5:$C$3741,2,0),0) -> 0 | E15: =IFERROR(VLOOKUP(B15,'TARIFA MASTER'!B11:L3466,3,0),0) -> 0 | F15: =IFERROR(VLOOKUP(B15,'TARIFA MASTER'!$B$15:$E$3702,4,0),0) -> 0 | G15: =IFERROR(VLOOKUP(B15,'TARIFA MASTER'!$B$5:$L$4699,11,0),0) -> 0 | H15: =IFERROR(VLOOKUP(B15,'TARIFA MASTER'!$B$5:$J$3754,5,0),0) -> 0 | K15: =IFERROR(VLOOKUP(B15,'TARIFA MASTER'!$B$5:$G$3752,6,0),0) -> 0 | L15: =+G15*C15 -> 0 | M15: =IFERROR(VLOOKUP(B15,[2]PESOS!A$2:D$3072,4,0),0) -> 0 | N15: =+M15*C15 -> 0
D16: =IFERROR(VLOOKUP(B16,'TARIFA MASTER'!$B$5:$C$3741,2,0),0) -> 0 | E16: =IFERROR(VLOOKUP(B16,'TARIFA MASTER'!B12:L3467,3,0),0) -> 0 | F16: =IFERROR(VLOOKUP(B16,'TARIFA MASTER'!$B$15:$E$3702,4,0),0) -> 0 | G16: =IFERROR(VLOOKUP(B16,'TARIFA MASTER'!$B$5:$L$4699,11,0),0) -> 0 | H16: =IFERROR(VLOOKUP(B16,'TARIFA MASTER'!$B$5:$J$3754,5,0),0) -> 0 | K16: =IFERROR(VLOOKUP(B16,'TARIFA MASTER'!$B$5:$G$3752,6,0),0) -> 0 | L16: =+G16*C16 -> 0 | M16: =IFERROR(VLOOKUP(B16,[2]PESOS!A$2:D$3072,4,0),0) -> 0 | N16: =+M16*C16 -> 0
D17: =IFERROR(VLOOKUP(B17,'TARIFA MASTER'!$B$5:$C$3741,2,0),0) -> 0 | E17: =IFERROR(VLOOKUP(B17,'TARIFA MASTER'!B13:L3471,3,0),0) -> 0 | F17: =IFERROR(VLOOKUP(B17,'TARIFA MASTER'!$B$15:$E$3702,4,0),0) -> 0 | G17: =IFERROR(VLOOKUP(B17,'TARIFA MASTER'!$B$5:$L$4699,11,0),0) -> 0 | H17: =IFERROR(VLOOKUP(B17,'TARIFA MASTER'!$B$5:$J$3754,5,0),0) -> 0 | K17: =IFERROR(VLOOKUP(B17,'TARIFA MASTER'!$B$5:$G$3752,6,0),0) -> 0 | L17: =+G17*C17 -> 0
D18: =IFERROR(VLOOKUP(B18,'TARIFA MASTER'!$B$5:$C$3741,2,0),0) -> 0 | E18: =IFERROR(VLOOKUP(B18,'TARIFA MASTER'!B15:L3472,3,0),0) -> 0 | F18: =IFERROR(VLOOKUP(B18,'TARIFA MASTER'!$B$15:$E$3702,4,0),0) -> 0 | G18: =IFERROR(VLOOKUP(B18,'TARIFA MASTER'!$B$5:$L$4699,11,0),0) -> 0 | H18: =IFERROR(VLOOKUP(B18,'TARIFA MASTER'!$B$5:$J$3754,5,0),0) -> 0 | K18: =IFERROR(VLOOKUP(B18,'TARIFA MASTER'!$B$5:$G$3752,6,0),0) -> 0 | L18: =+G18*C18 -> 0
D19: =IFERROR(VLOOKUP(B19,'TARIFA MASTER'!$B$5:$C$3741,2,0),0) -> 0 | E19: =IFERROR(VLOOKUP(B19,'TARIFA MASTER'!B15:L3473,3,0),0) -> 0 | F19: =IFERROR(VLOOKUP(B19,'TARIFA MASTER'!$B$15:$E$3702,4,0),0) -> 0 | G19: =IFERROR(VLOOKUP(B19,'TARIFA MASTER'!$B$5:$L$4699,11,0),0) -> 0 | H19: =IFERROR(VLOOKUP(B19,'TARIFA MASTER'!$B$5:$J$3754,5,0),0) -> 0 | K19: =IFERROR(VLOOKUP(B19,'TARIFA MASTER'!$B$5:$G$3752,6,0),0) -> 0 | L19: =+G19*C19 -> 0
D20: =IFERROR(VLOOKUP(B20,'TARIFA MASTER'!$B$5:$C$3741,2,0),0) -> 0 | E20: =IFERROR(VLOOKUP(B20,'TARIFA MASTER'!B15:L3474,3,0),0) -> 0 | F20: =IFERROR(VLOOKUP(B20,'TARIFA MASTER'!$B$15:$E$3702,4,0),0) -> 0 | G20: =IFERROR(VLOOKUP(B20,'TARIFA MASTER'!$B$5:$L$4699,11,0),0) -> 0 | H20: =IFERROR(VLOOKUP(B20,'TARIFA MASTER'!$B$5:$J$3754,5,0),0) -> 0 | K20: =IFERROR(VLOOKUP(B20,'TARIFA MASTER'!$B$5:$G$3752,6,0),0) -> 0 | L20: =+G20*C20 -> 0
D21: =IFERROR(VLOOKUP(B21,'TARIFA MASTER'!$B$5:$C$3741,2,0),0) -> 0 | E21: =IFERROR(VLOOKUP(B21,'TARIFA MASTER'!B15:L3475,3,0),0) -> 0 | F21: =IFERROR(VLOOKUP(B21,'TARIFA MASTER'!$B$15:$E$3702,4,0),0) -> 0 | G21: =IFERROR(VLOOKUP(B21,'TARIFA MASTER'!$B$5:$L$4699,11,0),0) -> 0 | H21: =IFERROR(VLOOKUP(B21,'TARIFA MASTER'!$B$5:$J$3754,5,0),0) -> 0 | K21: =IFERROR(VLOOKUP(B21,'TARIFA MASTER'!$B$5:$G$3752,6,0),0) -> 0 | L21: =+G21*C21 -> 0
D22: =IFERROR(VLOOKUP(B22,'TARIFA MASTER'!$B$5:$C$3741,2,0),0) -> 0 | E22: =IFERROR(VLOOKUP(B22,'TARIFA MASTER'!B15:L3476,3,0),0) -> 0 | F22: =IFERROR(VLOOKUP(B22,'TARIFA MASTER'!$B$15:$E$3702,4,0),0) -> 0 | G22: =IFERROR(VLOOKUP(B22,'TARIFA MASTER'!$B$5:$L$4699,11,0),0) -> 0 | H22: =IFERROR(VLOOKUP(B22,'TARIFA MASTER'!$B$5:$J$3754,5,0),0) -> 0 | K22: =IFERROR(VLOOKUP(B22,'TARIFA MASTER'!$B$5:$G$3752,6,0),0) -> 0 | L22: =+G22*C22 -> 0
D23: =IFERROR(VLOOKUP(B23,'TARIFA MASTER'!$B$5:$C$3741,2,0),0) -> 0 | E23: =IFERROR(VLOOKUP(B23,'TARIFA MASTER'!B15:L3477,3,0),0) -> 0 | F23: =IFERROR(VLOOKUP(B23,'TARIFA MASTER'!$B$15:$E$3702,4,0),0) -> 0 | G23: =IFERROR(VLOOKUP(B23,'TARIFA MASTER'!$B$5:$L$4699,11,0),0) -> 0 | H23: =IFERROR(VLOOKUP(B23,'TARIFA MASTER'!$B$5:$J$3754,5,0),0) -> 0 | K23: =IFERROR(VLOOKUP(B23,'TARIFA MASTER'!$B$5:$G$3752,6,0),0) -> 0 | L23: =+G23*C23 -> 0
D24: =IFERROR(VLOOKUP(B24,'TARIFA MASTER'!$B$5:$C$3741,2,0),0) -> 0 | E24: =IFERROR(VLOOKUP(B24,'TARIFA MASTER'!B15:L3477,3,0),0) -> 0 | F24: =IFERROR(VLOOKUP(B24,'TARIFA MASTER'!$B$15:$E$3702,4,0),0) -> 0 | G24: =IFERROR(VLOOKUP(B24,'TARIFA MASTER'!$B$5:$L$4699,11,0),0) -> 0 | H24: =IFERROR(VLOOKUP(B24,'TARIFA MASTER'!$B$5:$J$3754,5,0),0) -> 0 | K24: =IFERROR(VLOOKUP(B24,'TARIFA MASTER'!$B$5:$G$3752,6,0),0) -> 0 | L24: =+G24*C24 -> 0
D25: =IFERROR(VLOOKUP(B25,'TARIFA MASTER'!$B$5:$C$3741,2,0),0) -> 0 | E25: =IFERROR(VLOOKUP(B25,'TARIFA MASTER'!B15:L3478,3,0),0) -> 0 | F25: =IFERROR(VLOOKUP(B25,'TARIFA MASTER'!$B$15:$E$3702,4,0),0) -> 0 | G25: =IFERROR(VLOOKUP(B25,'TARIFA MASTER'!$B$5:$L$4699,11,0),0) -> 0 | H25: =IFERROR(VLOOKUP(B25,'TARIFA MASTER'!$B$5:$J$3754,5,0),0) -> 0 | K25: =IFERROR(VLOOKUP(B25,'TARIFA MASTER'!$B$5:$G$3752,6,0),0) -> 0 | L25: =+G25*C25 -> 0
D26: =IFERROR(VLOOKUP(B26,'TARIFA MASTER'!$B$5:$C$3741,2,0),0) -> 0 | E26: =IFERROR(VLOOKUP(B26,'TARIFA MASTER'!B15:L3479,3,0),0) -> 0 | F26: =IFERROR(VLOOKUP(B26,'TARIFA MASTER'!$B$15:$E$3702,4,0),0) -> 0 | G26: =IFERROR(VLOOKUP(B26,'TARIFA MASTER'!$B$5:$L$4699,11,0),0) -> 0 | H26: =IFERROR(VLOOKUP(B26,'TARIFA MASTER'!$B$5:$J$3754,5,0),0) -> 0 | K26: =IFERROR(VLOOKUP(B26,'TARIFA MASTER'!$B$5:$G$3752,6,0),0) -> 0 | L26: =+G26*C26 -> 0
D27: =IFERROR(VLOOKUP(B27,'TARIFA MASTER'!$B$5:$C$3741,2,0),0) -> 0 | E27: =IFERROR(VLOOKUP(B27,'TARIFA MASTER'!B15:L3479,3,0),0) -> 0 | F27: =IFERROR(VLOOKUP(B27,'TARIFA MASTER'!$B$15:$E$3702,4,0),0) -> 0 | G27: =IFERROR(VLOOKUP(B27,'TARIFA MASTER'!$B$5:$L$4699,11,0),0) -> 0 | H27: =IFERROR(VLOOKUP(B27,'TARIFA MASTER'!$B$5:$J$3754,5,0),0) -> 0 | K27: =IFERROR(VLOOKUP(B27,'TARIFA MASTER'!$B$5:$G$3752,6,0),0) -> 0 | L27: =+G27*C27 -> 0
D28: =IFERROR(VLOOKUP(B28,'TARIFA MASTER'!$B$5:$C$3741,2,0),0) -> 0 | E28: =IFERROR(VLOOKUP(B28,'TARIFA MASTER'!B15:L3480,3,0),0) -> 0 | F28: =IFERROR(VLOOKUP(B28,'TARIFA MASTER'!$B$15:$E$3702,4,0),0) -> 0 | G28: =IFERROR(VLOOKUP(B28,'TARIFA MASTER'!$B$5:$L$4699,11,0),0) -> 0 | H28: =IFERROR(VLOOKUP(B28,'TARIFA MASTER'!$B$5:$J$3754,5,0),0) -> 0 | K28: =IFERROR(VLOOKUP(B28,'TARIFA MASTER'!$B$5:$G$3752,6,0),0) -> 0 | L28: =+G28*C28 -> 0
D29: =IFERROR(VLOOKUP(B29,'TARIFA MASTER'!$B$5:$C$3741,2,0),0) -> 0 | E29: =IFERROR(VLOOKUP(B29,'TARIFA MASTER'!B15:L3481,3,0),0) -> 0 | F29: =IFERROR(VLOOKUP(B29,'TARIFA MASTER'!$B$15:$E$3702,4,0),0) -> 0 | G29: =IFERROR(VLOOKUP(B29,'TARIFA MASTER'!$B$5:$L$4699,11,0),0) -> 0 | H29: =IFERROR(VLOOKUP(B29,'TARIFA MASTER'!$B$5:$J$3754,5,0),0) -> 0 | K29: =IFERROR(VLOOKUP(B29,'TARIFA MASTER'!$B$5:$G$3752,6,0),0) -> 0 | L29: =+G29*C29 -> 0
D30: =IFERROR(VLOOKUP(B30,'TARIFA MASTER'!$B$5:$C$3741,2,0),0) -> 0 | E30: =IFERROR(VLOOKUP(B30,'TARIFA MASTER'!B15:L3482,3,0),0) -> 0 | F30: =IFERROR(VLOOKUP(B30,'TARIFA MASTER'!$B$15:$E$3702,4,0),0) -> 0 | G30: =IFERROR(VLOOKUP(B30,'TARIFA MASTER'!$B$5:$L$4699,11,0),0) -> 0 | H30: =IFERROR(VLOOKUP(B30,'TARIFA MASTER'!$B$5:$J$3754,5,0),0) -> 0 | K30: =IFERROR(VLOOKUP(B30,'TARIFA MASTER'!$B$5:$G$3752,6,0),0) -> 0 | L30: =+G30*C30 -> 0
D31: =IFERROR(VLOOKUP(B31,'TARIFA MASTER'!$B$5:$C$3741,2,0),0) -> 0 | E31: =IFERROR(VLOOKUP(B31,'TARIFA MASTER'!B15:L3483,3,0),0) -> 0 | F31: =IFERROR(VLOOKUP(B31,'TARIFA MASTER'!$B$15:$E$3702,4,0),0) -> 0 | G31: =IFERROR(VLOOKUP(B31,'TARIFA MASTER'!$B$5:$L$4699,11,0),0) -> 0 | H31: =IFERROR(VLOOKUP(B31,'TARIFA MASTER'!$B$5:$J$3754,5,0),0) -> 0 | K31: =IFERROR(VLOOKUP(B31,'TARIFA MASTER'!$B$5:$G$3752,6,0),0) -> 0 | L31: =+G31*C31 -> 0
D32: =IFERROR(VLOOKUP(B32,'TARIFA MASTER'!$B$5:$C$3741,2,0),0) -> 0 | E32: =IFERROR(VLOOKUP(B32,'TARIFA MASTER'!B15:L3484,3,0),0) -> 0 | F32: =IFERROR(VLOOKUP(B32,'TARIFA MASTER'!$B$15:$E$3702,4,0),0) -> 0 | G32: =IFERROR(VLOOKUP(B32,'TARIFA MASTER'!$B$5:$L$4699,11,0),0) -> 0 | H32: =IFERROR(VLOOKUP(B32,'TARIFA MASTER'!$B$5:$J$3754,5,0),0) -> 0 | K32: =IFERROR(VLOOKUP(B32,'TARIFA MASTER'!$B$5:$G$3752,6,0),0) -> 0 | L32: =+G32*C32 -> 0
D33: =IFERROR(VLOOKUP(B33,'TARIFA MASTER'!$B$5:$C$3741,2,0),0) -> 0 | E33: =IFERROR(VLOOKUP(B33,'TARIFA MASTER'!B15:L3485,3,0),0) -> 0 | F33: =IFERROR(VLOOKUP(B33,'TARIFA MASTER'!$B$15:$E$3702,4,0),0) -> 0 | G33: =IFERROR(VLOOKUP(B33,'TARIFA MASTER'!$B$5:$L$4699,11,0),0) -> 0 | H33: =IFERROR(VLOOKUP(B33,'TARIFA MASTER'!$B$5:$J$3754,5,0),0) -> 0 | K33: =IFERROR(VLOOKUP(B33,'TARIFA MASTER'!$B$5:$G$3752,6,0),0) -> 0 | L33: =+G33*C33 -> 0
D34: =IFERROR(VLOOKUP(B34,'TARIFA MASTER'!$B$5:$C$3741,2,0),0) -> 0 | E34: =IFERROR(VLOOKUP(B34,'TARIFA MASTER'!B15:L3486,3,0),0) -> 0 | F34: =IFERROR(VLOOKUP(B34,'TARIFA MASTER'!$B$15:$E$3702,4,0),0) -> 0 | G34: =IFERROR(VLOOKUP(B34,'TARIFA MASTER'!$B$5:$L$4699,11,0),0) -> 0 | H34: =IFERROR(VLOOKUP(B34,'TARIFA MASTER'!$B$5:$J$3754,5,0),0) -> 0 | K34: =IFERROR(VLOOKUP(B34,'TARIFA MASTER'!$B$5:$G$3752,6,0),0) -> 0 | L34: =+G34*C34 -> 0
D35: =IFERROR(VLOOKUP(B35,'TARIFA MASTER'!$B$5:$C$3741,2,0),0) -> 0 | E35: =IFERROR(VLOOKUP(B35,'TARIFA MASTER'!B15:L3487,3,0),0) -> 0 | F35: =IFERROR(VLOOKUP(B35,'TARIFA MASTER'!$B$15:$E$3702,4,0),0) -> 0 | G35: =IFERROR(VLOOKUP(B35,'TARIFA MASTER'!$B$5:$L$4699,11,0),0) -> 0 | H35: =IFERROR(VLOOKUP(B35,'TARIFA MASTER'!$B$5:$J$3754,5,0),0) -> 0 | K35: =IFERROR(VLOOKUP(B35,'TARIFA MASTER'!$B$5:$G$3752,6,0),0) -> 0 | L35: =+G35*C35 -> 0
D36: =IFERROR(VLOOKUP(B36,'TARIFA MASTER'!$B$5:$C$3741,2,0),0) -> 0 | E36: =IFERROR(VLOOKUP(B36,'TARIFA MASTER'!B15:L3488,3,0),0) -> 0 | F36: =IFERROR(VLOOKUP(B36,'TARIFA MASTER'!$B$15:$E$3702,4,0),0) -> 0 | G36: =IFERROR(VLOOKUP(B36,'TARIFA MASTER'!$B$5:$L$4699,11,0),0) -> 0 | H36: =IFERROR(VLOOKUP(B36,'TARIFA MASTER'!$B$5:$J$3754,5,0),0) -> 0 | K36: =IFERROR(VLOOKUP(B36,'TARIFA MASTER'!$B$5:$G$3752,6,0),0) -> 0 | L36: =+G36*C36 -> 0
D37: =IFERROR(VLOOKUP(B37,'TARIFA MASTER'!$B$5:$C$3741,2,0),0) -> 0 | E37: =IFERROR(VLOOKUP(B37,'TARIFA MASTER'!B15:L3489,3,0),0) -> 0 | F37: =IFERROR(VLOOKUP(B37,'TARIFA MASTER'!$B$15:$E$3702,4,0),0) -> 0 | G37: =IFERROR(VLOOKUP(B37,'TARIFA MASTER'!$B$5:$L$4699,11,0),0) -> 0 | H37: =IFERROR(VLOOKUP(B37,'TARIFA MASTER'!$B$5:$J$3754,5,0),0) -> 0 | K37: =IFERROR(VLOOKUP(B37,'TARIFA MASTER'!$B$5:$G$3752,6,0),0) -> 0 | L37: =+G37*C37 -> 0
D38: =IFERROR(VLOOKUP(B38,'TARIFA MASTER'!$B$5:$C$3741,2,0),0) -> 0 | E38: =IFERROR(VLOOKUP(B38,'TARIFA MASTER'!B15:L3490,3,0),0) -> 0 | F38: =IFERROR(VLOOKUP(B38,'TARIFA MASTER'!$B$15:$E$3702,4,0),0) -> 0 | G38: =IFERROR(VLOOKUP(B38,'TARIFA MASTER'!$B$5:$L$4699,11,0),0) -> 0 | H38: =IFERROR(VLOOKUP(B38,'TARIFA MASTER'!$B$5:$J$3754,5,0),0) -> 0 | K38: =IFERROR(VLOOKUP(B38,'TARIFA MASTER'!$B$5:$G$3752,6,0),0) -> 0 | L38: =+G38*C38 -> 0
D39: =IFERROR(VLOOKUP(B39,'TARIFA MASTER'!$B$5:$C$3741,2,0),0) -> 0 | E39: =IFERROR(VLOOKUP(B39,'TARIFA MASTER'!B15:L3491,3,0),0) -> 0 | F39: =IFERROR(VLOOKUP(B39,'TARIFA MASTER'!$B$15:$E$3702,4,0),0) -> 0 | G39: =IFERROR(VLOOKUP(B39,'TARIFA MASTER'!$B$5:$L$4699,11,0),0) -> 0 | H39: =IFERROR(VLOOKUP(B39,'TARIFA MASTER'!$B$5:$J$3754,5,0),0) -> 0 | K39: =IFERROR(VLOOKUP(B39,'TARIFA MASTER'!$B$5:$G$3752,6,0),0) -> 0 | L39: =+G39*C39 -> 0
D40: =IFERROR(VLOOKUP(B40,'TARIFA MASTER'!$B$5:$C$3741,2,0),0) -> 0 | E40: =IFERROR(VLOOKUP(B40,'TARIFA MASTER'!B15:L3492,3,0),0) -> 0 | F40: =IFERROR(VLOOKUP(B40,'TARIFA MASTER'!$B$15:$E$3702,4,0),0) -> 0 | G40: =IFERROR(VLOOKUP(B40,'TARIFA MASTER'!$B$5:$L$4699,11,0),0) -> 0 | H40: =IFERROR(VLOOKUP(B40,'TARIFA MASTER'!$B$5:$J$3754,5,0),0) -> 0 | K40: =IFERROR(VLOOKUP(B40,'TARIFA MASTER'!$B$5:$G$3752,6,0),0) -> 0 | L40: =+G40*C40 -> 0
D41: =IFERROR(VLOOKUP(B41,'TARIFA MASTER'!$B$5:$C$3741,2,0),0) -> 0 | E41: =IFERROR(VLOOKUP(B41,'TARIFA MASTER'!B15:L3493,3,0),0) -> 0 | F41: =IFERROR(VLOOKUP(B41,'TARIFA MASTER'!$B$15:$E$3702,4,0),0) -> 0 | G41: =IFERROR(VLOOKUP(B41,'TARIFA MASTER'!$B$5:$L$4699,11,0),0) -> 0 | H41: =IFERROR(VLOOKUP(B41,'TARIFA MASTER'!$B$5:$J$3754,5,0),0) -> 0 | K41: =IFERROR(VLOOKUP(B41,'TARIFA MASTER'!$B$5:$G$3752,6,0),0) -> 0 | L41: =+G41*C41 -> 0
D42: =IFERROR(VLOOKUP(B42,'TARIFA MASTER'!$B$5:$C$3741,2,0),0) -> 0 | E42: =IFERROR(VLOOKUP(B42,'TARIFA MASTER'!B16:L3494,3,0),0) -> 0 | F42: =IFERROR(VLOOKUP(B42,'TARIFA MASTER'!$B$15:$E$3702,4,0),0) -> 0 | G42: =IFERROR(VLOOKUP(B42,'TARIFA MASTER'!$B$5:$L$4699,11,0),0) -> 0 | H42: =IFERROR(VLOOKUP(B42,'TARIFA MASTER'!$B$5:$J$3754,5,0),0) -> 0 | K42: =IFERROR(VLOOKUP(B42,'TARIFA MASTER'!$B$5:$G$3752,6,0),0) -> 0 | L42: =+G42*C42 -> 0
D43: =IFERROR(VLOOKUP(B43,'TARIFA MASTER'!$B$5:$C$3741,2,0),0) -> 0 | E43: =IFERROR(VLOOKUP(B43,'TARIFA MASTER'!B17:L3495,3,0),0) -> 0 | F43: =IFERROR(VLOOKUP(B43,'TARIFA MASTER'!$B$15:$E$3702,4,0),0) -> 0 | G43: =IFERROR(VLOOKUP(B43,'TARIFA MASTER'!$B$5:$L$4699,11,0),0) -> 0 | H43: =IFERROR(VLOOKUP(B43,'TARIFA MASTER'!$B$5:$J$3754,5,0),0) -> 0 | K43: =IFERROR(VLOOKUP(B43,'TARIFA MASTER'!$B$5:$G$3752,6,0),0) -> 0 | L43: =+G43*C43 -> 0
...

Sheet TARIFA MASTER
C1: REFUERZO | D1: ACC | E1: WHALL PANEL | F1: PISOS | G1: ZOCALOS | H1: CIELO RASO | J1: TUBULARES | N1: TUBULARES
B2: ='PLANILLA PEDIDO'!C3 -> 0 | C2: ='PLANILLA PEDIDO'!C4 -> 0 | D2: ='PLANILLA PEDIDO'!C5 -> 0 | E2: ='PLANILLA PEDIDO'!E3 -> 0 | F2: ='PLANILLA PEDIDO'!G3 -> 0 | G2: ='PLANILLA PEDIDO'!G5 -> 0 | H2: ='PLANILLA PEDIDO'!E4 -> 0 | J2: ='PLANILLA PEDIDO'!E5 -> 0 | K2: 0.05 | N2: 0
B4: Codigo | C4: DESCRIPCIÓN PERFILES PRINCIPALES | D4: Masa | E4: Folio | F4: UNIDAD | G4: PRESENTACIÓN | I4: p unt /ml | J4: FACTURACIÓN u$s | K4: u$d | L4: U$D DESC
B5: 413231000 | C5: Contravidrio ECO | D5: BLANCA | E5: BLANCO | F5: 1 | G5: Paq x 10 unid | H5: 5.8 | I5: =J5/10/5.8 -> 0.32571724 | J5: 18.8916 | K5: =J5 -> 18.8916 | L5: =+J5-K5*$B$2 -> 18.8916 | N5: 18.165 | O5: =N5*1.04 -> 18.8916
B6: 413241000 | C6: Contravidrio DVH ECO | D6: BLANCA | E6: BLANCO | F6: 1 | G6: Paq x 10 unid | H6: 5.8 | I6: =J6/10/5.8 -> 0.23323836 | J6: 13.527825 | K6: =J6 -> 13.527825 | L6: =+J6-K6*$B$2 -> 13.527825 | N6: 13.007524 | O6: =N6*1.04 -> 13.527825
B7: 610281000 | C7: Hoja ECO | D7: BLANCA | E7: BLANCO | F7: 6 | G7: tira | H7: 5.8 | I7: =J7/H7 -> 1.9505379 | J7: 11.31312 | K7: =J7 -> 11.31312 | L7: =+J7-K7*$B$2 -> 11.31312 | N7: 10.878 | O7: =N7*1.04 -> 11.31312
B8: 610291000 | C8: Hoja Guillotina | D8: BLANCA | E8: BLANCO | F8: 6 | G8: tira | H8: 5.8 | I8: =J8/H8 -> 2.1463448 | J8: 12.4488 | K8: =J8 -> 12.4488 | L8: =+J8-K8*$B$2 -> 12.4488 | N8: 11.97 | O8: =N8*1.04 -> 12.4488
B9: 611031000 | C9: Poste Movil ECO | D9: BLANCA | E9: BLANCO | F9: 1 | G9: tira | H9: 5.8 | I9: =J9/H9 -> 2.4794684 | J9: 14.380917 | K9: =J9 -> 14.380917 | L9: =+J9-K9*$B$2 -> 14.380917 | N9: 13.827804 | O9: =N9*1.04 -> 14.380917
B10: 611041000 | C10: Poste Fijo ECO | D10: BLANCA | E10: BLANCO | F10: 4 | G10: tira | H10: 5.8 | I10: =J10/H10 -> 2.4833586 | J10: 14.40348 | K10: =J10 -> 14.40348 | L10: =+J10-K10*$B$2 -> 14.40348 | N10: 13.8495 | O10: =N10*1.04 -> 14.40348
B11: 612381000 | C11: Marco ECO sin Aleta | D11: BLANCA | E11: BLANCO | F11: 4 | G11: tira | H11: 5.8 | I11: =J11/H11 -> 4.1891379 | J11: 24.297 | K11: =J11 -> 24.297 | L11: =+J11-K11*$B$2 -> 24.297 | N11: 23.3625 | O11: =N11*1.04 -> 24.297
B12: 613091000 | C12: Guia ECO BCO | D12: BLANCA | E12: BLANCO | F12: 10 | G12: tira | H12: 5.8 | I12: =J12/H12 -> 0.98844828 | J12: 5.733 | K12: =J12 -> 5.733 | L12: =+J12-K12*$B$2 -> 5.733 | N12: 5.5125 | O12: =N12*1.04 -> 5.733
B13: 612371000 | C13: Marco ECO con Aleta | D13: BLANCA | E13: BLANCO | F13: 4 | G13: tira | H13: 5.8 | I13: =J13/H13 -> 4.3981241 | J13: 25.50912 | K13: =J13 -> 25.50912 | L13: =+J13-K13*$B$2 -> 25.50912 | N13: 24.528 | O13: =N13*1.04 -> 25.50912
B14: 613081000 | C14: Cover Eco | D14: BLANCA | E14: BLANCO | F14: 10 | G14: tira | H14: 5.8 | I14: =+J14/5.8 -> 0.99033103 | J14: 5.74392 | K14: =J14 -> 5.74392 | L14: =+J14-K14*$B$2 -> 5.74392 | N14: 5.523 | O14: =N14*1.04 -> 5.74392
B15: 612161000 | C15: Marco MiniSlide | D15: BLANCA | E15: SIN FOLIO | F15: 1 | G15: tira | H15: 5.8 | I15: =J15/H15 -> 3.149517 | J15: 18.267199 | K15: =J15 -> 18.267199 | L15: =+J15-K15*$B$2 -> 18.267199 | N15: 17.564614 | O15: =N15*1.04 -> 18.267199
B16: 612162000 | C16: Marco MiniSlide | D16: MARFIL | E16: SIN FOLIO | F16: 1 | G16: tira | H16: 5.8 | I16: =J16/H16 -> 3.0224448 | J16: 17.53018 | K16: =J16 -> 17.53018 | L16: =+J16-K16*$B$2 -> 17.53018 | N16: 16.855942 | O16: =N16*1.04 -> 17.53018
B17: 612164013 | C17: Marco MiniSlide | D17: MARFIL | E17: GOLDEN OAK | F17: 1 | G17: tira | H17: 5.8 | I17: =J17/H17 -> 6.1619061 | J17: 35.739055 | K17: =J17 -> 35.739055 | L17: =+J17-K17*$B$2 -> 35.739055 | N17: 34.364476 | O17: =N17*1.04 -> 35.739055
B18: 612163093 | C18: Marco MiniSlide | D18: GRIS | E18: GRIS METALIZADO | F18: 1 | G18: tira | H18: 5.8 | I18: =J18/H18 -> 6.6244283 | J18: 38.421684 | K18: =J18 -> 38.421684 | L18: =+J18-K18*$B$2 -> 38.421684 | N18: 36.943927 | O18: =N18*1.04 -> 38.421684
B19: 612164103 | C19: Marco MiniSlide | D19: MARRON | E19: NOGAL | F19: 1 | G19: tira | H19: 5.8 | I19: =J19/H19 -> 6.1619061 | J19: 35.739055 | K19: =J19 -> 35.739055 | L19: =+J19-K19*$B$2 -> 35.739055 | N19: 34.364476 | O19: =N19*1.04 -> 35.739055
B20: 612162143 | C20: Marco MiniSlide | D20: MARFIL | E20: PELTRE | F20: 1 | G20: tira | H20: 5.8 | I20: =J20/H20 -> 6.652232 | J20: 38.582946 | K20: =J20 -> 38.582946 | L20: =+J20-K20*$B$2 -> 38.582946 | N20: 37.098986 | O20: =N20*1.04 -> 38.582946
B21: 612163283 | C21: Marco MiniSlide | D21: GRIS | E21: JET BLACK | F21: 1 | G21: tira | H21: 5.8 | I21: =J21/H21 -> 7.9705641 | J21: 46.229272 | K21: =J21 -> 46.229272 | L21: =+J21-K21*$B$2 -> 46.229272 | N21: 44.451223 | O21: =N21*1.04 -> 46.229272
B22: 612165283 | C22: Marco MiniSlide | D22: NEGRA | E22: JET BLACK | F22: 1 | G22: tira | H22: 5.8 | I22: =J22/H22 -> 7.9705641 | J22: 46.229272 | K22: =J22 -> 46.229272 | L22: =+J22-K22*$B$2 -> 46.229272 | N22: 44.451223 | O22: =N22*1.04 -> 46.229272
B23: 612165413 | C23: Marco MiniSlide | D23: NEGRA | E23: Matex Kitami | F23: 1 | G23: tira | H23: 5.8 | I23: =J23/H23 -> 8.3026709 | J23: 48.155491 | K23: =J23 -> 48.155491 | L23: =+J23-K23*$B$2 -> 48.155491 | N23: 46.303357 | O23: =N23*1.04 -> 48.155491
B24: 612162243 | C24: Marco MiniSlide | D24: MARFIL | E24: TURNER OAK | F24: 1 | G24: tira | H24: 5.8 | I24: =J24/H24 -> 8.0891965 | J24: 46.91734 | K24: =J24 -> 46.91734 | L24: =+J24-K24*$B$2 -> 46.91734 | N24: 45.112826 | O24: =N24*1.04 -> 46.91734
B25: 612164183 | C25: Marco MiniSlide | D25: MARRON | E25: LENGA | F25: 1 | G25: tira | H25: 5.8 | I25: =J25/H25 -> 7.0942836 | J25: 41.146845 | K25: =J25 -> 41.146845 | L25: =+J25-K25*$B$2 -> 41.146845 | N25: 36.926192 | O25: =N25*1.04 -> 38.40324
B26: 612163113 | C26: Marco MiniSlide | D26: GRIS | E26: GRIS GRAFITO | F26: 1 | G26: tira | H26: 5.8 | I26: =J26/H26 -> 6.1953823 | J26: 35.933217 | K26: =J26 -> 35.933217 | L26: =+J26-K26*$B$2 -> 35.933217 | N26: 34.551171 | O26: =N26*1.04 -> 35.933217
... B32: 610155280 | C32: Hoja MiniSlide | D32: NEGRA | E32: JET BLACK | F32: 1 | G32: tira | H32: 5.8 | I32: =J32/H32 -> 6.9661262 | J32: 40.403532 | K32: =J32 -> 40.403532 | L32: =+J32-K32*$B$2 -> 40.403532 | N32: 38.84955 | O32: =N32*1.04 -> 40.403532
B33: 610155070 | C33: Hoja MiniSlide | D33: NEGRA | E33: Black Matt | F33: 1 | G33: tira | H33: 5.8 | I33: =J33/H33 -> 6.4745487 | J33: 37.552383 | K33: =J33 -> 37.552383 | L33: =+J33-K33*$B$2 -> 37.552383
B34: 610155410 | C34: Hoja MiniSlide | D34: NEGRA | E34: Matex Kitami | F34: 1 | G34: tira | H34: 5.8 | I34: =J34/H34 -> 7.1827865 | J34: 41.660162 | K34: =J34 -> 41.660162 | L34: =+J34-K34*$B$2 -> 41.660162 | N34: 40.057848 | O34: =N34*1.04 -> 41.660162
B35: 612165073 | C35: Marco MiniSlide BLACK MATT | D35: NEGRA | E35: Black Matt | F35: 1 | G35: tira | H35: 5.8 | I35: =J35/H35 -> 6.873227 | J35: 39.864717 | K35: =J35 -> 39.864717 | L35: =+J35-K35*$B$2 -> 39.864717
B36: 610152240 | C36: Hoja MiniSlide | D36: MARFIL | E36: TURNER OAK | F36: 1 | G36: tira | H36: 5.8 | I36: =J36/H36 -> 7.8587519 | J36: 45.580761 | K36: =J36 -> 45.580761 | L36: =+J36-K36*$B$2 -> 45.580761 | N36: 43.827655 | O36: =N36*1.04 -> 45.580761
B37: 610151370 | C37: Hoja MiniSlide | D37: BLANCA | E37: ALPINE | F37: 1 | G37: tira | H37: 5.8 | I37: =J37/H37 -> 7.1520631 | J37: 41.481966 | K37: =J37 -> 41.481966 | L37: =+J37-K37*$B$2 -> 41.481966 | N37: 39.886506 | O37: =N37*1.04 -> 41.481966
B38: 610154360 | C38: Hoja MiniSlide | D38: MARRON | E38: TOFFE | F38: 1 | G38: tira | H38: 5.8 | I38: =J38/H38 -> 7.1520631 | J38: 41.481966 | K38: =J38 -> 41.481966 | L38: =+J38-K38*$B$2 -> 41.481966 | N38: 39.886506 | O38: =N38*1.04 -> 41.481966
B39: 610154390 | C39: Hoja MiniSlide | D39: MARRON | E39: GOLDBRONZE | F39: 1 | G39: tira | H39: 5.8 | I39: =J39/H39 -> 7.5656257 | J39: 43.880629 | K39: =J39 -> 43.880629 | L39: =+J39-K39*$B$2 -> 43.880629 | N39: 42.192912 | O39: =N39*1.04 -> 43.880629
B40: 610154180 | C40: Hoja MiniSlide | D40: MARRON | E40: LENGA | F40: 1 | G40: tira | H40: 5.8 | I40: =J40/H40 -> 6.848717 | J40: 39.722559 | K40: =J40 -> 39.722559 | L40: =+J40-K40*$B$2 -> 39.722559 | N40: 33.783543 | O40: =N40*1.04 -> 35.134884
B41: 610153110 | C41: Hoja MiniSlide | D41: GRIS | E41: GRIS GRAFITO | F41: 1 | G41: tira | H41: 5.8 | I41: =J41/H41 -> 5.7042399 | J41: 33.084591 | K41: =J41 -> 33.084591 | L41: =+J41-K41*$B$2 -> 33.084591 | N41: 31.812107 | O41: =N41*1.04 -> 33.084591
B42: 610153520 | C42: Hoja MiniSlide | D42: GRIS | E42: WHITE ALUM | F42: 1 | G42: tira | H42: 5.8 | I42: =J42/H42 -> 6.6732151 | J42: 38.704647 | K42: =J42 -> 38.704647 | L42: =+J42-K42*$B$2 -> 38.704647 | N42: 37.216007 | O42: =N42*1.04 -> 38.704647
B43: 610155050 | C43: Hoja MiniSlide | D43: NEGRA | E43: Umbra grau | F43: 1 | G43: tira | H43: 5.8 | I43: =J43/H43 -> 6.9662069 | J43: 40.404 | K43: =J43 -> 40.404 | L43: =+J43-K43*$B$2 -> 40.404 | N43: 38.85 | O43: =N43*1.04 -> 40.404
B44: 613031000 | C44: Encuentro MiniSlide | D44: BLANCA | E44: SIN FOLIO | F44: 10 | G44: tira | H44: 5.8 | I44: =J44/H44 -> 0.80130005 | J44: 4.6475403 | K44: =J44 -> 4.6475403 | L44: =+J44-K44*$B$2 -> 4.6475403 | N44: 4.4687887 | O44: =N44*1.04 -> 4.6475403
B45: 613032000 | C45: Encuentro MiniSlide | D45: MARFIL | E45: SIN FOLIO | F45: 10 | G45: tira | H45: 5.8 | I45: =J45/H45 -> 0.84458631 | J45: 4.8986006 | K45: =J45 -> 4.8986006 | L45: =+J45-K45*$B$2 -> 4.8986006 | N45: 4.7101929 | O45: =N45*1.04 -> 4.8986006
B46: 613034010 | C46: Encuentro MiniSlide | D46: MARRON | E46: GOLDEN OAK | F46: 10 | G46: tira | H46: 5.8 | I46: =J46/H46 -> 1.2989009 | J46: 7.5336251 | K46: =J46 -> 7.5336251 | L46: =+J46-K46*$B$2 -> 7.5336251 | N46: 7.2438703 | O46: =N46*1.04 -> 7.5336251
...

Sheet  LAMINA PERFILES

Sheet TUBULAR 58 X 58
B1: PERFIL TUBULAR 58 X 58 mm | G1: =+TODAY() -> 46148
E3: completar solo la parte en verde | G3: ANCHO METROS | H3: ALTO METROS | AD3: PLANILLA PEDIDO
C4: COLOR | E4: LENGA | G4: 4
E5: =E6*10 -> 0
C6: CANTIDAD | E6: 0 | G6: HORIENTACION | H6: vertical
C8: REF CANTIDAD | E8: 0
E9: 0
C11: TAPAS CANT | E11: 41
H13: =#REF!*10 -> #REF!
C14: CODIGO | E14: DESCRIPCION | F14: PRE.UNIT | G14: CANTIDAD | H14: TOTAL
B15: B- | C15: =IFERROR(VLOOKUP(E4,M78:N96,2,0),0) -> 913370180 | E15: Perfil tubular 38 x 76 mm | F15: =VLOOKUP(C15,'TARIFA MASTER'!B15:J3408,9,0) -> 64.109886 | G15: =E6 -> 0 | H15: =+G15*F15 -> 0
B16: C- | C16: 920370015 | E16: refuerzo acero | F16: =IFERROR(VLOOKUP(C16,'[1]TARIFA MASTER'!C$46:K$2442,9,0),0) -> 53.162122 | G16: =E8 -> 0 | H16: =F16*G16 -> 0
C18: =J76 -> 0 | F18: TUBULARES | G18: 0.2 | H18: =H15-(H15*G18) -> 0
F20: REFUERZO | G20: 0 | H20: =H16-(H16*G20) -> 0
F22: REF ALUMINIO | G22: 0 | H22: =IF(#REF!="aluminio",H16-(H16*G22),0) -> #REF!
G25: TOTAL | H25: =SUM(H18+H20) -> 0
M27: ALUMINIO | Q27: 55.56 | R27: 51.3764
C28: A - Los valores están expresados en dólares, no incluyen impuestos | M28: ACERO | Q28: 25 | R28: 66.6101
C30: B - Este cotizador solo contempla tira standard (5800mm) de tubular con refuerzo
C31: * Unidad de embalaje
C32: tubular | E32: por tira 5,8 METROS
C33: refuerzos | E33: por tira 3 METROS
C35: D- Para un cómputo más detallado, se recomienda optimizar su proyecto en Autocad.
C37: E - Los descuentos corresponden a los asignados en PVC /REFUERZO
H45: peso 38 x 38
M78: GOLDEN OAK | N78: 913370010
M79: NATURAL OAK | N79: 913370020
M80: JET BLACK | N80: 913370280
M81: GRIS METALIZADO | N81: 913370090
M82: NOGAL | N82: 913370100
M83: GRIS GRAFITO | N83: 913370110
M84: SCHWARTZBRAUN | N84: 913370120
M85: WENGUE | N85: 913370250
M86: GREY OAK | N86: 913370270
M87: BLANCO ALTWEISSE | N87: 913370380
M88: ALPINE | N88: 913370370
M89: TOFFEE | N89: 913370360
... M96: GEN ALUM | N96: 913370520

Sheet  CIELORRASO EXT
C1: completar solo la parte en verde | E1: =ROUNDUP(D7,0) -> 2 | H1: =ROUNDUP(G7,0) -> 2 | I1: =+TODAY() -> 46148 | L1: =ROUNDUP(J7,0) -> 1
B2: CIELORASO | E2: MOLDURA EN " L " | H2: MOLDURA | I2: =+I4/5.8 -> 15.689655 | K2: UNION CIELO RASO
B3: COLOR | C3: CONCRET_C_ | E3: COLOR | F3: EUCALYPTUS | H3: COLOR | I3: EUCALYPTUS | K3: COLOR | L3: EUCALYPTUS
B4: M² | C4: 12 | E4: CANT ML | F4: 92 | H4: CANT ML | I4: 91 | K4: CANT ML | L4: 20
B5: UN EMB 10 TABLAS de CIELORRASO = 12 M² | E5: UN EMB 30 TIRAS = 90 Mts Lineales | H5: UN EMB 30 TIRAS = 3Mts Lineales x Tira | K5: UN EMB 10 TIRAS = 3Mts Lineales x Tira
A6: =ROUNDUP(A7,0) -> 1
A7: =+C4/12 -> 1 | B7: PAQUETE | C7: =A6 -> 1 | D7: =F4/90 -> 1.0222222 | E7: PAQUETE | F7: =E1 -> 2 | G7: =I4/90 -> 1.0111111 | H7: PAQUETE | I7: =H1 -> 2 | J7: =L4/30 -> 0.66666667 | K7: PAQUETE | L7: =L1 -> 1
A8: =A6*10 -> 10 | B8: TOTAL TABLAS | C8: =A8 -> 10 | D8: =F7*30 -> 60 | E8: TOTAL TIRAS | F8: =D8 -> 60 | G8: =I7*30 -> 60 | H8: TOTAL TIRAS | I8: =G8 -> 60 | J8: =L7*10 -> 10 | K8: TOTAL TIRAS | L8: =J8 -> 10
B10: CODIGO | C10: DESCRIPCION | D10: PRE.UNIT | E10: CANTIDAD | F10: TOTAL
A11: =+#REF!+#REF! -> #REF! | B11: =IFERROR(VLOOKUP(C3,B36:C44,2,0),0) -> 913610500 | C11: CIELO RASO | D11: =IFERROR(VLOOKUP(B11,'[1]TARIFA MASTER'!C$46:K$2442,9,0),0) -> 24 | E11: =C8 -> 10 | F11: =IFERROR((D11*E11),"") -> 240
B12: =VLOOKUP(F3,H36:I43,2,0) -> 913620440 | C12: MOLDURA " L " | D12: =IFERROR(VLOOKUP(B12,'[1]TARIFA MASTER'!C$46:K$2442,9,0),0) -> 4.2376758 | E12: =F8 -> 60 | F12: =IFERROR((D12*E12),"") -> 254.26055
B13: =VLOOKUP(I3,B45:C52,2,0) -> 913630440 | C13: MOLDURA | D13: =IFERROR(VLOOKUP(B13,'[1]TARIFA MASTER'!C$46:K$2442,9,0),0) -> 6.0353594 | E13: =I8 -> 60 | F13: =IFERROR((D13*E13),"") -> 362.12156
B14: =VLOOKUP(L3,H45:I52,2,0) -> 913640440 | C14: UNION CIELO RASO | D14: =IFERROR(VLOOKUP(B14,'[1]TARIFA MASTER'!C$46:K$2442,9,0),0) -> 7.1147245 | E14: =L8 -> 10 | F14: =IFERROR((D14*E14),"") -> 71.147245
E16: SUB TOTAL | F16: =SUM(F11:F14) -> 927.52936 | K16: MOLDURA L | M16: UNION
K17: =ROUNDUP(K29,0) -> 31 | L17: =ROUNDUP(L29,0) -> 31 | M17: =ROUNDUP(M29,0) -> 7
D18: DESC | E18: 0.1 | F18: =(F16*E18) -> 92.752936
E20: TOTAL | F20: =+F16-F18 -> 834.77642
K21: 2606
B26: =I4*10% -> 9.1
K29: =F4/3 -> 30.666667 | L29: =I4/3 -> 30.333333 | M29: =L4/3 -> 6.6666667
A31: A - Los valores están expresados en dólares, no incluyen impuestos
A32: B - Este cotizador solo contempla tira standard (3000 mm Molduras / 6000 mm para CIELO RASO)
A33: C - Para un cómputo más detallado, se recomienda optimizar su proyecto en Autocad.
A34: D- Los descuentos corresponden a los asignados en PVC
B36: BLANCO_ | C36: 913611000 | D36: Cielorraso BCO | H36: BLANCO | I36: 913621000 | J36: Perimetral L BCO
B37: OAK_ | C37: 913610430 | D37: Cielorraso GEN OAK | H37: OAK | I37: 913620430 | J37: Perimetral L GEN OAK
B38: EUCALIPTUS_ | C38: 913610440 | D38: Cieloraso GEN EUC | H38: EUCALYPTUS | I38: 913620440 | J38: Perimetral L GEN EUC
B39: POPLAR_ | C39: 913610450 | D39: Cieloraso GEN POP | H39: POPLAR | I39: 913620450 | J39: Perimetral L GEN POP
B40: WALNUT_ | C40: 913610460 | D40: Cieloraso GEN WAL | H40: WALNUT | I40: 913620460 | J40: Perimetral L GEN WAL
B41: TEAK_ | C41: 913610470 | D41: Cieloraso GEN TEEK | H41: TEEK | I41: 913620470 | J41: Perimetral L GEN TEEK
B42: CONCRET_WITE_ | C42: 913610490 | D42: Cieloraso GEN WCON | H42: WHITE CONCRETE | I42: 913620490 | J42: Perimetral L GEN WCON
B43: CONCRET_C_ | C43: 913610500 | D43: Cieloraso GEN CONC | H43: CONCRETE C | I43: 913620500 | J43: Perimetral L GEN CONC
B45: BLANCO | C45: 913631000 | D45: Perimetral Moldura BCO | H45: BLANCO | I45: 913641000 | J45: Union Cielorraso BCO
B46: OAK | C46: 913630430 | D46: Perimetral Moldura GEN OAK | H46: OAK | I46: 913640430 | J46: Union Cielorraso GEN OAK
B47: EUCALYPTUS | C47: 913630440 | D47: Perimetral Moldura GEN EUC | H47: EUCALYPTUS | I47: 913640440 | J47: Union Cielorraso GEN EUC
B48: POPLAR | C48: 913630450 | D48: Perimetral Moldura GEN POP | H48: POPLAR | I48: 913640450 | J48: Union Cielorraso GEN POP
B49: WALNUT | C49: 913630460 | D49: Perimetral Moldura GEN WAL | H49: WALNUT | I49: 913640460 | J49: Union Cielorraso GEN WAL
... B52: CONCRETE C | C52: 913630500 | D52: Perimetral Moldura GEN CONC | H52: CONCRETE C | I52: 913640500 | J52: Union Cielorraso GEN CONC
C57: 0
C58: 12
...

Sheet PESOS
A1: Codigo | B1: DESCRIPCIÓN PERFILES PRINCIPALES | C1: Presentacion | D1: peso OK
A2: 110101000 | B2: Perfil de PVC Hoja Dz 46-89 BLANCO | C2: tira | D2: 7.74
A3: 110101010 | B3: Perfil de PVC LAMINADO Hoja Dz 46-89 GOLDEN OAK | C3: tira | D3: 8.15
A4: 110101011 | B4: Perfil de PVC LAMINADO Hoja Dz 46-89 GOLDEN OAK | C4: tira | D4: 8
A5: 110101012 | B5: Perfil de PVC LAMINADO Hoja Dz 46-89 GOLDEN OAK | C5: tira | D5: 7.95
A6: 110101020 | B6: Perfil de PVC LAMINADO Hoja Dz 46-89 NATURAL OAK | C6: tira | D6: 8.15
A7: 110101021 | B7: Perfil de PVC LAMINADO Hoja Dz 46-89 NATURAL OAK | C7: tira | D7: 8
A8: 110101022 | B8: Perfil de PVC LAMINADO Hoja Dz 46-89 NATURAL OAK | C8: tira | D8: 7.95
A9: 110101060 | B9: Perfil de PVC LAMINADO Hoja Dz 46-89 VERDE | C9: tira | D9: 8.15
A10: 110101061 | B10: Perfil de PVC LAMINADO Hoja Dz 46-89 VERDE | C10: tira | D10: 8
A11: 110101062 | B11: Perfil de PVC LAMINADO Hoja Dz 46-89 VERDE | C11: tira | D11: 7.95
A12: 110101080 | B12: Perfil de PVC LAMINADO Hoja Dz 46-89 CHERRY | C12: tira | D12: 8.15
A13: 110101081 | B13: Perfil de PVC LAMINADO Hoja Dz 46-89 CHERRY | C13: tira | D13: 8
... A2776: 945705000 | B2776: Adaptador Refuerzo 20x23 mm de plastico | C2776: un | D2776: 0.025
A2777: 01-6061-1Q | B2777: Panel siding doble 4 `` Smoke characol de pvc | C2777: 24 tiras | D2777: 1.78
A2778: 01-6061-3T | B2778: Panel siding doble 4 `` English Saddle de pvc | C2778: 24 tiras | D2778: 1.78
A2779: 01-6061-V7 | B2779: Panel siding doble 4 `` Antique Parchment de pvc | C2779: 24 tiras | D2779: 1.78
A2780: 10-3956-1Q | B2780: PVC Trim Coil Smoke characol 1Q de pvc | C2780: rollo | D2780: 12.72
A2781: 10-3956-3T | B2781: PVC Trim Coil English Saddle 3T de pvc | C2781: rollo | D2781: 12.72
A2782: 10-3956-V7 | B2782: PVC Trim Coil Antique Parchment V7 de pvc | C2782: rollo | D2782: 12.72
A2783: 10-5053-1Q | B2783: Perfil de PVC Esquinero interior Smoke characol | C2783: tira | D2783: 0.99
A2784: 10-5053-V7 | B2784: Perfil de PVC Esquinero interior Antique Parchment | C2784: tira | D2784: 0.99
A2785: 10-5118-1Q | B2785: Perfil de PVC canal J 3/4`` Smoke characol | C2785: tira | D2785: 0.72
A2786: 10-5118-3T | B2786: Perfil de PVC canal J 3/4`` English Saddle | C2786: tira | D2786: 0.72
A2787: 10-5118-V7 | B2787: Perfil de PVC canal J 3/4`` Antique Parchment | C2787: tira | D2787: 0.72
A2788: 10-5200-1Q | B2788: Perfil de PVC de terminacion Smoke characol | C2788: tira | D2788: 0.46
... A2793: 10-5644-3T | B2793: Perfil de PVC Esquinero exterior 4`` English Saddle | C2793: tira | D2793: 2.03
A2794: 10-7361 | B2794: Perfil de inicio 2 1/2`` Galvanizado de acero galvanizado | C2794: tira | D2794: #N/A
A2795: 76-0010 | B2795: Destrabador de paneles Siding PVC - ZIP Tool de metal | C2795: un | D2795: 0.1
A2796: 76-7203 | B2796: Pinza para realizar lengüetas Siding PVC - Snap Lock punch de metal | C2796: un | D2796: 0.3
A2797: 76-8062 | B2797: Tijera especial para Siding PVC – Snip de metal | C2797: un | D2797: 0.44
A2798: B.2400H100B | B2798: Kit marco Blanco 2460 x 100 Blanca de WPC | C2798: un | D2798: 16.5
A2799: B.2400H140B | B2799: Kit marco Blanco 2460 x 140 Blanca de WPC | C2799: un | D2799: 18
A2800: B.2400H180B | B2800: Kit marco Blanco 2460 x 180 Blanca de WPC | C2800: un | D2800: 19
A2801: B.2400H220B | B2801: Kit marco Blanco 2460 x 220 Blanca de WPC | C2801: un | D2801: 20
A2802: B.KA10.900X2050NH7 | B2802: Hoja Lisa Blanca x7mm 900 x 2050 Blanca de WPC | C2802: un | D2802: 38
A2803: B.KL01.700X2050BSH | B2803: Hoja buña Blanca calada 700 X 2050 Blanca de WPC | C2803: un | D2803: 22.5
A2804: B.KL01.800X2050BSH | B2804: Hoja buña Blanca calada 800 X 2050 Blanca de WPC | C2804: un | D2804: 22.5
A2805: B.KL01.800X2400BSH | B2805: Hoja buña Blanca calada 800 X 2400 Blanca de WPC | C2805: un | D2805: 26.3
A2806: B.KL01.900X2050BSH | B2806: Hoja buña Blanca calada 900X 2050 Blanca de WPC | C2806: un | D2806: 26.5
...
